<?xml version="1.0"?>
<robot xmlns:xacro="http://wiki.ros.org/xacro">

  <xacro:property name="DEG2RAD" value="0.017453292519943295"/>

  <xacro:macro name="kuka_kr60" params="prefix">
		<xacro:macro name="transmission_block" params="joint_name">
			<transmission name="tran1">
				<type>transmission_interface/SimpleTransmission</type>
				<joint name="${joint_name}">
					<hardwareInterface>hardware_interface/PositionJointInterface</hardwareInterface>
				</joint>
				<actuator name="motor1">
					<hardwareInterface>hardware_interface/PositionJointInterface</hardwareInterface>
					<mechanicalReduction>1</mechanicalReduction>
				</actuator>
			</transmission>
		</xacro:macro>

    <!-- LINKS -->
    <!-- base link -->
    <link name="${prefix}base_link">
      <inertial>
        <origin xyz="-0.0436791859512302 0.000756993325450678 0.241811297515981" rpy="0 0 0"/>
        <mass value="2"/>
        <inertia ixx="0.01" ixy="0" ixz="0" iyy="0.01" iyz="0" izz="0.01" />
      </inertial>
      <visual>
        <origin xyz="0 0 0" rpy="0 0 0"/>
        <geometry>
          <mesh filename="package://kuka_kr60_support/meshes/base_link.dae" />
        </geometry>
				<material name="orange"/>
      </visual>
      <collision>
        <origin xyz="0 0 0" rpy="0 0 0"/>
        <geometry>
          <mesh filename="package://kuka_kr60_support/meshes/base_link.STL" />
        </geometry>
      </collision>
    </link>

    <!-- link 1 (A1) -->
    <link name="${prefix}link_1">
      <inertial>
        <origin xyz="0.140775001892144 0.211684256508182 -0.014282449384274" rpy="0 0 0"/>
        <mass value="2"/>
        <inertia ixx="0.01" ixy="0" ixz="0" iyy="0.01" iyz="0" izz="0.01" />
      </inertial>
      <visual>
        <origin xyz="0 0 0" rpy="0 0 0"/>
        <geometry>
          <mesh
          filename="package://kuka_kr60_support/meshes/link_1.dae" />
        </geometry>
				<material name="orange"/>
      </visual>
      <collision>
        <origin xyz="0 0 0" rpy="0 0 0"/>
        <geometry>
         <mesh
          filename="package://kuka_kr60_support/meshes/link_1.STL" />
        </geometry>
      </collision>
    </link>
    <!-- link 2 -->
    <link name="${prefix}link_2">
      <inertial>
        <origin xyz="0.382307904215314 -0.16306654546705 0.000499911356832916" rpy="0 0 0"/>
        <mass value="2"/>
        <inertia ixx="0.01" ixy="0" ixz="0" iyy="0.01" iyz="0" izz="0.01" />
      </inertial>
      <visual>
        <origin xyz="0 0 0" rpy="0 0 0"/>
        <geometry>
          <mesh filename="package://kuka_kr60_support/meshes/link_2.dae"/>
        </geometry>
				<material name="orange"/>
      </visual>
      <collision>
        <origin xyz="0 0 0" rpy="0 0 0"/>
        <geometry>
          <mesh filename="package://kuka_kr60_support/meshes/link_2.STL" />
        </geometry>
      </collision>
    </link>
    <!-- link 3 -->
    <link name="${prefix}link_3">
      <inertial>
        <origin xyz="0.0224104444574682 0.107197329797912 0.0695655063110385" rpy="0 0 0"/>
        <mass value="2"/>
        <inertia ixx="0.01" ixy="0" ixz="0" iyy="0.01" iyz="0" izz="0.01" />
      </inertial>
      <visual>
        <origin xyz="0 0 0" rpy="0 0 0"/>
        <geometry>
          <mesh filename="package://kuka_kr60_support/meshes/link_3.dae" />
        </geometry>
				<material name="orange"/>
      </visual>
      <collision>
        <origin xyz="0 0 0" rpy="0 0 0"/>
        <geometry>
          <mesh filename="package://kuka_kr60_support/meshes/link_3.STL" />
        </geometry>
      </collision>
    </link>
    <!-- link 4 -->
    <link name="${prefix}link_4">
      <inertial>
        <origin xyz="0.195695132615539 -0.0107352464057435 0.000109040539318039" rpy="0 0 0"/>
        <mass value="2"/>
        <inertia ixx="0.01" ixy="0" ixz="0" iyy="0.01" iyz="0" izz="0.01" />
      </inertial>
      <visual>
        <origin xyz="0 0 0" rpy="0 0 0"/>
        <geometry>
          <mesh filename="package://kuka_kr60_support/meshes/link_4.dae" />
        </geometry>
				<material name="orange"/>
      </visual>
      <collision>
        <origin xyz="0 0 0" rpy="0 0 0"/>
        <geometry>
          <mesh filename="package://kuka_kr60_support/meshes/link_4.STL" />
        </geometry>
      </collision>
    </link>
    <!-- link 5 -->
    <link name="${prefix}link_5">
      <inertial>
        <origin xyz="0.0258909572353643 0.0172714930553038 2.77581030716512E-06" rpy="0 0 0"/>
        <mass value="2"/>
        <inertia ixx="0.01" ixy="0" ixz="0" iyy="0.01" iyz="0" izz="0.01" />
      </inertial>
      <visual>
        <origin xyz="0 0 0" rpy="0 0 0"/>
        <geometry>
          <mesh filename="package://kuka_kr60_support/meshes/link_5.dae" />
        </geometry>
				<material name="orange"/>
      </visual>
      <collision>
        <origin xyz="0 0 0" rpy="0 0 0"/>
        <geometry>
          <mesh filename="package://kuka_kr60_support/meshes/link_5.STL" />
        </geometry>
      </collision>
    </link>
    <!-- link 6 -->
    <link name="${prefix}link_6">
      <inertial>
        <origin xyz="0.0169571197340979 5.10153992383522E-08 -7.36285182980634E-05" rpy="0 0 0"/>
        <mass value="2"/>
        <inertia ixx="0.01" ixy="0" ixz="0" iyy="0.01" iyz="0" izz="0.01" />
      </inertial>
      <visual>
        <origin xyz="0 0 0" rpy="0 0 0"/>
        <geometry>
          <mesh filename="package://kuka_kr60_support/meshes/link_6.dae" />
        </geometry>
				<material name="orange"/>
      </visual>
      <collision>
        <origin xyz="0 0 0" rpy="0 0 0"/>
        <geometry>
          <mesh filename="package://kuka_kr60_support/meshes/link_6.STL" />
        </geometry>
      </collision>
    </link>
    <!-- tool 0 -->
    <!-- This frame corresponds to the $FLANGE coordinate system in KUKA KRC controllers. -->
    <link name="${prefix}tool0"/>


 <!-- tool 0 -->
    <!-- This frame corresponds to the $FLANGE coordinate system in KUKA KRC controllers. -->
    <!-- END LINKS -->

    <!-- JOINTS -->
    <!-- joint 1 (A1) -->
    <joint name="${prefix}joint_a1" type="revolute">
      <origin xyz="0 0 0.47975" rpy="1.5708 0 0"/>
      <parent link="${prefix}base_link"/>
      <child link="${prefix}link_1"/>
      <axis xyz="0 -1 0"/>
      <limit effort="0" lower="-3.22" upper="3.22" velocity="${DEG2RAD * 156}"/>
			<hardwareInterface>hardware_interface/PositionJointInterface</hardwareInterface>    
    </joint>

    <!-- joint 2 (A2) -->
    <joint name="${prefix}joint_a2" type="revolute">
      <origin xyz="0.35 0.33557 0.094" rpy="-1.5708 0 0"/>
      <parent link="${prefix}link_1"/>
      <child link="${prefix}link_2"/>
      <axis xyz="0 1 0"/>
      <limit effort="0" lower="-2.35" upper="0.61" velocity="${DEG2RAD * 156}"/>
			<hardwareInterface>hardware_interface/PositionJointInterface</hardwareInterface> 
    </joint>
    <!-- joint 3 (A3) -->
    <joint name="${prefix}joint_a3" type="revolute">
      <origin xyz="0.83287 -0.0097315 0" rpy="0 0 -0.011684"/>
      <parent link="${prefix}link_2"/>
      <child link="${prefix}link_3"/>
      <axis xyz="0 1 0"/>
      <limit effort="0" lower="-2.09" upper="2.75" velocity="${DEG2RAD * 156}"/>
			<hardwareInterface>hardware_interface/PositionJointInterface</hardwareInterface> 
    </joint>
    <!-- joint 4 (A4) -->
    <joint name="${prefix}joint_a4" type="revolute">
      <origin xyz="0.60824 0.089904 0.145" rpy="0 0 0"/>
      <parent link="${prefix}link_3"/>
      <child link="${prefix}link_4"/>
      <axis xyz="-1 0 0"/>
      <limit effort="0" lower="-6.1" upper="6.1" velocity="${DEG2RAD * 156}"/>
			<hardwareInterface>hardware_interface/PositionJointInterface</hardwareInterface> 
    </joint>
    <!-- joint 5 (A5) -->
    <joint name="${prefix}joint_a5" type="revolute">
      <origin xyz="0.41176 0 6.3846E-05" rpy="0 -0.00079387 0.011684"/>
      <parent link="${prefix}link_4"/>
      <child link="${prefix}link_5"/>
      <axis xyz="0.011683 0.99993 0"/>
      <limit effort="0" lower="-2.07" upper="2.07" velocity="${DEG2RAD * 330}"/>
			<hardwareInterface>hardware_interface/PositionJointInterface</hardwareInterface> 
    </joint>
    <!-- joint 6 (A6) -->
    <joint name="${prefix}joint_a6" type="revolute">
			<!--
      <origin xyz="0.12607 -3.6549E-05 -2.8142E-05" rpy="-0.67012 0.00079387 0"/>
			-->
			
      <origin xyz="0.12607 -3.6549E-05 -2.8142E-05" rpy="0 0 0"/>
      <parent link="${prefix}link_5"/>
      <child link="${prefix}link_6"/>
      <axis xyz="-1 0 0"/>
      <limit effort="0" lower="-6.1" upper="6.1" velocity="${DEG2RAD * 156}"/>
			<hardwareInterface>hardware_interface/PositionJointInterface</hardwareInterface> 
    </joint>
    <!-- tool frame - fixed frame -->
    <joint name="${prefix}joint_a6-tool0" type="fixed">
      <parent link="${prefix}link_6"/>
      <child link="${prefix}tool0"/>
      <origin xyz="0.038 0 0" rpy="0 ${DEG2RAD * 90} 0"/>
			<hardwareInterface>hardware_interface/PositionJointInterface</hardwareInterface> 
    </joint>
    <!-- END JOINTS -->

    <!-- ROS base_link to KUKA $ROBROOT coordinate system transform  -->


		<xacro:transmission_block joint_name="${prefix}joint_a1"/>
		<xacro:transmission_block joint_name="${prefix}joint_a2"/>
		<xacro:transmission_block joint_name="${prefix}joint_a3"/>
		<xacro:transmission_block joint_name="${prefix}joint_a4"/>
		<xacro:transmission_block joint_name="${prefix}joint_a5"/>
		<xacro:transmission_block joint_name="${prefix}joint_a6"/>


		 <!-- ros_control plugin -->
  <gazebo>
    <plugin name="gazebo_ros_control" filename="libgazebo_ros_control.so">
      <robotNamespace>/kuka_kr60</robotNamespace>
    </plugin>
  </gazebo>

  </xacro:macro>

</robot>


