<?xml version="1.0" ?>
<!-- =================================================================================== -->
<!-- |    This document was autogenerated by xacro from kuka_kr60_support/urdf/UM_KR60_setup.xacro | -->
<!-- |    EDITING THIS FILE BY HAND IS NOT RECOMMENDED                                 | -->
<!-- =================================================================================== -->
<!--Generates a urdf from the macro in kr120r2500pro_macro.xacro -->
<robot name="UM_KR60_setup" xmlns:xacro="http://wiki.ros.org/xacro">
  <link name="world"/>
  <!-- LINKS -->
  <!-- base link -->
  <link name="left_base_link">
    <inertial>
      <origin rpy="0 0 0" xyz="-0.0436791859512302 0.000756993325450678 0.241811297515981"/>
      <mass value="2"/>
      <inertia ixx="0.01" ixy="0" ixz="0" iyy="0.01" iyz="0" izz="0.01"/>
    </inertial>
    <visual>
      <origin rpy="0 0 0" xyz="0 0 0"/>
      <geometry>
        <mesh filename="package://kuka_kr60_support/meshes/base_link.dae"/>
      </geometry>
      <material name="orange"/>
    </visual>
    <collision>
      <origin rpy="0 0 0" xyz="0 0 0"/>
      <geometry>
        <mesh filename="package://kuka_kr60_support/meshes/base_link.STL"/>
      </geometry>
    </collision>
  </link>
  <!-- link 1 (A1) -->
  <link name="left_link_1">
    <inertial>
      <origin rpy="0 0 0" xyz="0.140775001892144 0.211684256508182 -0.014282449384274"/>
      <mass value="2"/>
      <inertia ixx="0.01" ixy="0" ixz="0" iyy="0.01" iyz="0" izz="0.01"/>
    </inertial>
    <visual>
      <origin rpy="0 0 0" xyz="0 0 0"/>
      <geometry>
        <mesh filename="package://kuka_kr60_support/meshes/link_1.dae"/>
      </geometry>
      <material name="orange"/>
    </visual>
    <collision>
      <origin rpy="0 0 0" xyz="0 0 0"/>
      <geometry>
        <mesh filename="package://kuka_kr60_support/meshes/link_1.STL"/>
      </geometry>
    </collision>
  </link>
  <!-- link 2 -->
  <link name="left_link_2">
    <inertial>
      <origin rpy="0 0 0" xyz="0.382307904215314 -0.16306654546705 0.000499911356832916"/>
      <mass value="2"/>
      <inertia ixx="0.01" ixy="0" ixz="0" iyy="0.01" iyz="0" izz="0.01"/>
    </inertial>
    <visual>
      <origin rpy="0 0 0" xyz="0 0 0"/>
      <geometry>
        <mesh filename="package://kuka_kr60_support/meshes/link_2.dae"/>
      </geometry>
      <material name="orange"/>
    </visual>
    <collision>
      <origin rpy="0 0 0" xyz="0 0 0"/>
      <geometry>
        <mesh filename="package://kuka_kr60_support/meshes/link_2.STL"/>
      </geometry>
    </collision>
  </link>
  <!-- link 3 -->
  <link name="left_link_3">
    <inertial>
      <origin rpy="0 0 0" xyz="0.0224104444574682 0.107197329797912 0.0695655063110385"/>
      <mass value="2"/>
      <inertia ixx="0.01" ixy="0" ixz="0" iyy="0.01" iyz="0" izz="0.01"/>
    </inertial>
    <visual>
      <origin rpy="0 0 0" xyz="0 0 0"/>
      <geometry>
        <mesh filename="package://kuka_kr60_support/meshes/link_3.dae"/>
      </geometry>
      <material name="orange"/>
    </visual>
    <collision>
      <origin rpy="0 0 0" xyz="0 0 0"/>
      <geometry>
        <mesh filename="package://kuka_kr60_support/meshes/link_3.STL"/>
      </geometry>
    </collision>
  </link>
  <!-- link 4 -->
  <link name="left_link_4">
    <inertial>
      <origin rpy="0 0 0" xyz="0.195695132615539 -0.0107352464057435 0.000109040539318039"/>
      <mass value="2"/>
      <inertia ixx="0.01" ixy="0" ixz="0" iyy="0.01" iyz="0" izz="0.01"/>
    </inertial>
    <visual>
      <origin rpy="0 0 0" xyz="0 0 0"/>
      <geometry>
        <mesh filename="package://kuka_kr60_support/meshes/link_4.dae"/>
      </geometry>
      <material name="orange"/>
    </visual>
    <collision>
      <origin rpy="0 0 0" xyz="0 0 0"/>
      <geometry>
        <mesh filename="package://kuka_kr60_support/meshes/link_4.STL"/>
      </geometry>
    </collision>
  </link>
  <!-- link 5 -->
  <link name="left_link_5">
    <inertial>
      <origin rpy="0 0 0" xyz="0.0258909572353643 0.0172714930553038 2.77581030716512E-06"/>
      <mass value="2"/>
      <inertia ixx="0.01" ixy="0" ixz="0" iyy="0.01" iyz="0" izz="0.01"/>
    </inertial>
    <visual>
      <origin rpy="0 0 0" xyz="0 0 0"/>
      <geometry>
        <mesh filename="package://kuka_kr60_support/meshes/link_5.dae"/>
      </geometry>
      <material name="orange"/>
    </visual>
    <collision>
      <origin rpy="0 0 0" xyz="0 0 0"/>
      <geometry>
        <mesh filename="package://kuka_kr60_support/meshes/link_5.STL"/>
      </geometry>
    </collision>
  </link>
  <!-- link 6 -->
  <link name="left_link_6">
    <inertial>
      <origin rpy="0 0 0" xyz="0.0169571197340979 5.10153992383522E-08 -7.36285182980634E-05"/>
      <mass value="2"/>
      <inertia ixx="0.01" ixy="0" ixz="0" iyy="0.01" iyz="0" izz="0.01"/>
    </inertial>
    <visual>
      <origin rpy="0 0 0" xyz="0 0 0"/>
      <geometry>
        <mesh filename="package://kuka_kr60_support/meshes/link_6.dae"/>
      </geometry>
      <material name="orange"/>
    </visual>
    <collision>
      <origin rpy="0 0 0" xyz="0 0 0"/>
      <geometry>
        <mesh filename="package://kuka_kr60_support/meshes/link_6.STL"/>
      </geometry>
    </collision>
  </link>
  <!-- tool 0 -->
  <!-- This frame corresponds to the $FLANGE coordinate system in KUKA KRC controllers. -->
  <link name="left_tool0"/>
  <!-- tool 0 -->
  <!-- This frame corresponds to the $FLANGE coordinate system in KUKA KRC controllers. -->
  <!--OCIMA Gripper-->
  <link name="left_gripper">
    <inertial>
      <origin rpy="0 0 0" xyz="-0.0428764766835783 -0.013530986668562 -0.0481091446071806"/>
      <mass value="4.45066934712782"/>
      <inertia ixx="0.0280534429483876" ixy="0.00203411158636486" ixz="-0.00280489820899368" iyy="0.12704521558317" iyz="-0.000926853755642866" izz="0.107306139125527"/>
    </inertial>
    <visual>
      <origin rpy="0 0 0" xyz="0 0 0"/>
      <geometry>
        <mesh filename="package://gripper_ocima/meshes/base_link.dae"/>
      </geometry>
      <material name="Orange">
        <!--<color rgba="1 0.49 0.31 1" />-->
      </material>
    </visual>
    <collision>
      <origin rpy="0 0 0" xyz="0 0 0"/>
      <geometry>
        <mesh filename="package://gripper_ocima/meshes/base_link.STL"/>
      </geometry>
    </collision>
  </link>
  <!-- END LINKS -->
  <!-- JOINTS -->
  <!-- joint 1 (A1) -->
  <joint name="left_joint_a1" type="revolute">
    <origin rpy="1.5708 0 0" xyz="0 0 0.47975"/>
    <parent link="left_base_link"/>
    <child link="left_link_1"/>
    <axis xyz="0 -1 0"/>
    <limit effort="0" lower="-3.22" upper="3.22" velocity="2.72271363311"/>
    <hardwareInterface>hardware_interface/PositionJointInterface</hardwareInterface>
  </joint>
  <!-- joint 2 (A2) -->
  <joint name="left_joint_a2" type="revolute">
    <origin rpy="-1.5708 0 0" xyz="0.35 0.33557 0.094"/>
    <parent link="left_link_1"/>
    <child link="left_link_2"/>
    <axis xyz="0 1 0"/>
    <limit effort="0" lower="-2.35" upper="0.61" velocity="2.72271363311"/>
    <hardwareInterface>hardware_interface/PositionJointInterface</hardwareInterface>
  </joint>
  <!-- joint 3 (A3) -->
  <joint name="left_joint_a3" type="revolute">
    <origin rpy="0 0 -0.011684" xyz="0.83287 -0.0097315 0"/>
    <parent link="left_link_2"/>
    <child link="left_link_3"/>
    <axis xyz="0 1 0"/>
    <limit effort="0" lower="-2.09" upper="2.75" velocity="2.72271363311"/>
    <hardwareInterface>hardware_interface/PositionJointInterface</hardwareInterface>
  </joint>
  <!-- joint 4 (A4) -->
  <joint name="left_joint_a4" type="revolute">
    <origin rpy="0 0 0" xyz="0.60824 0.089904 0.145"/>
    <parent link="left_link_3"/>
    <child link="left_link_4"/>
    <axis xyz="-1 0 0"/>
    <limit effort="0" lower="-6.1" upper="6.1" velocity="2.72271363311"/>
    <hardwareInterface>hardware_interface/PositionJointInterface</hardwareInterface>
  </joint>
  <!-- joint 5 (A5) -->
  <joint name="left_joint_a5" type="revolute">
    <origin rpy="0 -0.00079387 0.011684" xyz="0.41176 0 6.3846E-05"/>
    <parent link="left_link_4"/>
    <child link="left_link_5"/>
    <axis xyz="0.011683 0.99993 0"/>
    <limit effort="0" lower="-2.07" upper="2.07" velocity="5.75958653158"/>
    <hardwareInterface>hardware_interface/PositionJointInterface</hardwareInterface>
  </joint>
  <!-- joint 6 (A6) -->
  <joint name="left_joint_a6" type="revolute">
    <!--
      <origin xyz="0.12607 -3.6549E-05 -2.8142E-05" rpy="-0.67012 0.00079387 0"/>
			-->
    <origin rpy="0 0 0" xyz="0.12607 -3.6549E-05 -2.8142E-05"/>
    <parent link="left_link_5"/>
    <child link="left_link_6"/>
    <axis xyz="-1 0 0"/>
    <limit effort="0" lower="-6.1" upper="6.1" velocity="2.72271363311"/>
    <hardwareInterface>hardware_interface/PositionJointInterface</hardwareInterface>
  </joint>
  <!-- tool frame - fixed frame -->
  <joint name="left_joint_a6-tool0" type="fixed">
    <parent link="left_link_6"/>
    <child link="left_tool0"/>
    <origin rpy="0 1.57079632679 0" xyz="0.215 0 0"/>
    <hardwareInterface>hardware_interface/PositionJointInterface</hardwareInterface>
  </joint>
  <!-- gripper frame - fixed frame -->
  <joint name="left_tool0-gripper" type="fixed">
    <parent link="left_tool0"/>
    <child link="left_gripper"/>
    <origin rpy="-1.57079632679 0 1.57079632679" xyz="0.41 -0.33 -0.02"/>
  </joint>
  <!-- END JOINTS -->
  <!-- ROS base_link to KUKA $ROBROOT coordinate system transform  -->
  <joint name="left_grounding" type="fixed">
    <parent link="world"/>
    <child link="left_base_link"/>
    <origin rpy="0.0 0.0 0.0" xyz="0.0 -2.390051 0.0"/>
  </joint>
  <transmission name="tran1">
    <type>transmission_interface/SimpleTransmission</type>
    <joint name="left_joint_a1">
      <hardwareInterface>hardware_interface/PositionJointInterface</hardwareInterface>
    </joint>
    <actuator name="motor1">
      <hardwareInterface>hardware_interface/PositionJointInterface</hardwareInterface>
      <mechanicalReduction>1</mechanicalReduction>
    </actuator>
  </transmission>
  <transmission name="tran1">
    <type>transmission_interface/SimpleTransmission</type>
    <joint name="left_joint_a2">
      <hardwareInterface>hardware_interface/PositionJointInterface</hardwareInterface>
    </joint>
    <actuator name="motor1">
      <hardwareInterface>hardware_interface/PositionJointInterface</hardwareInterface>
      <mechanicalReduction>1</mechanicalReduction>
    </actuator>
  </transmission>
  <transmission name="tran1">
    <type>transmission_interface/SimpleTransmission</type>
    <joint name="left_joint_a3">
      <hardwareInterface>hardware_interface/PositionJointInterface</hardwareInterface>
    </joint>
    <actuator name="motor1">
      <hardwareInterface>hardware_interface/PositionJointInterface</hardwareInterface>
      <mechanicalReduction>1</mechanicalReduction>
    </actuator>
  </transmission>
  <transmission name="tran1">
    <type>transmission_interface/SimpleTransmission</type>
    <joint name="left_joint_a4">
      <hardwareInterface>hardware_interface/PositionJointInterface</hardwareInterface>
    </joint>
    <actuator name="motor1">
      <hardwareInterface>hardware_interface/PositionJointInterface</hardwareInterface>
      <mechanicalReduction>1</mechanicalReduction>
    </actuator>
  </transmission>
  <transmission name="tran1">
    <type>transmission_interface/SimpleTransmission</type>
    <joint name="left_joint_a5">
      <hardwareInterface>hardware_interface/PositionJointInterface</hardwareInterface>
    </joint>
    <actuator name="motor1">
      <hardwareInterface>hardware_interface/PositionJointInterface</hardwareInterface>
      <mechanicalReduction>1</mechanicalReduction>
    </actuator>
  </transmission>
  <transmission name="tran1">
    <type>transmission_interface/SimpleTransmission</type>
    <joint name="left_joint_a6">
      <hardwareInterface>hardware_interface/PositionJointInterface</hardwareInterface>
    </joint>
    <actuator name="motor1">
      <hardwareInterface>hardware_interface/PositionJointInterface</hardwareInterface>
      <mechanicalReduction>1</mechanicalReduction>
    </actuator>
  </transmission>
  <!-- ros_control plugin -->
  <gazebo>
    <plugin filename="libgazebo_ros_control.so" name="gazebo_ros_control">
      <robotNamespace>/kuka_kr60</robotNamespace>
    </plugin>
  </gazebo>
  <!-- LINKS -->
  <!-- base link -->
  <link name="right_base_link">
    <inertial>
      <origin rpy="0 0 0" xyz="-0.0436791859512302 0.000756993325450678 0.241811297515981"/>
      <mass value="2"/>
      <inertia ixx="0.01" ixy="0" ixz="0" iyy="0.01" iyz="0" izz="0.01"/>
    </inertial>
    <visual>
      <origin rpy="0 0 0" xyz="0 0 0"/>
      <geometry>
        <mesh filename="package://kuka_kr60_support/meshes/base_link.dae"/>
      </geometry>
      <material name="orange"/>
    </visual>
    <collision>
      <origin rpy="0 0 0" xyz="0 0 0"/>
      <geometry>
        <mesh filename="package://kuka_kr60_support/meshes/base_link.STL"/>
      </geometry>
    </collision>
  </link>
  <!-- link 1 (A1) -->
  <link name="right_link_1">
    <inertial>
      <origin rpy="0 0 0" xyz="0.140775001892144 0.211684256508182 -0.014282449384274"/>
      <mass value="2"/>
      <inertia ixx="0.01" ixy="0" ixz="0" iyy="0.01" iyz="0" izz="0.01"/>
    </inertial>
    <visual>
      <origin rpy="0 0 0" xyz="0 0 0"/>
      <geometry>
        <mesh filename="package://kuka_kr60_support/meshes/link_1.dae"/>
      </geometry>
      <material name="orange"/>
    </visual>
    <collision>
      <origin rpy="0 0 0" xyz="0 0 0"/>
      <geometry>
        <mesh filename="package://kuka_kr60_support/meshes/link_1.STL"/>
      </geometry>
    </collision>
  </link>
  <!-- link 2 -->
  <link name="right_link_2">
    <inertial>
      <origin rpy="0 0 0" xyz="0.382307904215314 -0.16306654546705 0.000499911356832916"/>
      <mass value="2"/>
      <inertia ixx="0.01" ixy="0" ixz="0" iyy="0.01" iyz="0" izz="0.01"/>
    </inertial>
    <visual>
      <origin rpy="0 0 0" xyz="0 0 0"/>
      <geometry>
        <mesh filename="package://kuka_kr60_support/meshes/link_2.dae"/>
      </geometry>
      <material name="orange"/>
    </visual>
    <collision>
      <origin rpy="0 0 0" xyz="0 0 0"/>
      <geometry>
        <mesh filename="package://kuka_kr60_support/meshes/link_2.STL"/>
      </geometry>
    </collision>
  </link>
  <!-- link 3 -->
  <link name="right_link_3">
    <inertial>
      <origin rpy="0 0 0" xyz="0.0224104444574682 0.107197329797912 0.0695655063110385"/>
      <mass value="2"/>
      <inertia ixx="0.01" ixy="0" ixz="0" iyy="0.01" iyz="0" izz="0.01"/>
    </inertial>
    <visual>
      <origin rpy="0 0 0" xyz="0 0 0"/>
      <geometry>
        <mesh filename="package://kuka_kr60_support/meshes/link_3.dae"/>
      </geometry>
      <material name="orange"/>
    </visual>
    <collision>
      <origin rpy="0 0 0" xyz="0 0 0"/>
      <geometry>
        <mesh filename="package://kuka_kr60_support/meshes/link_3.STL"/>
      </geometry>
    </collision>
  </link>
  <!-- link 4 -->
  <link name="right_link_4">
    <inertial>
      <origin rpy="0 0 0" xyz="0.195695132615539 -0.0107352464057435 0.000109040539318039"/>
      <mass value="2"/>
      <inertia ixx="0.01" ixy="0" ixz="0" iyy="0.01" iyz="0" izz="0.01"/>
    </inertial>
    <visual>
      <origin rpy="0 0 0" xyz="0 0 0"/>
      <geometry>
        <mesh filename="package://kuka_kr60_support/meshes/link_4.dae"/>
      </geometry>
      <material name="orange"/>
    </visual>
    <collision>
      <origin rpy="0 0 0" xyz="0 0 0"/>
      <geometry>
        <mesh filename="package://kuka_kr60_support/meshes/link_4.STL"/>
      </geometry>
    </collision>
  </link>
  <!-- link 5 -->
  <link name="right_link_5">
    <inertial>
      <origin rpy="0 0 0" xyz="0.0258909572353643 0.0172714930553038 2.77581030716512E-06"/>
      <mass value="2"/>
      <inertia ixx="0.01" ixy="0" ixz="0" iyy="0.01" iyz="0" izz="0.01"/>
    </inertial>
    <visual>
      <origin rpy="0 0 0" xyz="0 0 0"/>
      <geometry>
        <mesh filename="package://kuka_kr60_support/meshes/link_5.dae"/>
      </geometry>
      <material name="orange"/>
    </visual>
    <collision>
      <origin rpy="0 0 0" xyz="0 0 0"/>
      <geometry>
        <mesh filename="package://kuka_kr60_support/meshes/link_5.STL"/>
      </geometry>
    </collision>
  </link>
  <!-- link 6 -->
  <link name="right_link_6">
    <inertial>
      <origin rpy="0 0 0" xyz="0.0169571197340979 5.10153992383522E-08 -7.36285182980634E-05"/>
      <mass value="2"/>
      <inertia ixx="0.01" ixy="0" ixz="0" iyy="0.01" iyz="0" izz="0.01"/>
    </inertial>
    <visual>
      <origin rpy="0 0 0" xyz="0 0 0"/>
      <geometry>
        <mesh filename="package://kuka_kr60_support/meshes/link_6.dae"/>
      </geometry>
      <material name="orange"/>
    </visual>
    <collision>
      <origin rpy="0 0 0" xyz="0 0 0"/>
      <geometry>
        <mesh filename="package://kuka_kr60_support/meshes/link_6.STL"/>
      </geometry>
    </collision>
  </link>
  <!-- tool 0 -->
  <!-- This frame corresponds to the $FLANGE coordinate system in KUKA KRC controllers. -->
  <link name="right_tool0"/>
  <!-- tool 0 -->
  <!-- This frame corresponds to the $FLANGE coordinate system in KUKA KRC controllers. -->
  <!--OCIMA Gripper-->
  <link name="right_gripper">
    <inertial>
      <origin rpy="0 0 0" xyz="-0.0428764766835783 -0.013530986668562 -0.0481091446071806"/>
      <mass value="4.45066934712782"/>
      <inertia ixx="0.0280534429483876" ixy="0.00203411158636486" ixz="-0.00280489820899368" iyy="0.12704521558317" iyz="-0.000926853755642866" izz="0.107306139125527"/>
    </inertial>
    <visual>
      <origin rpy="0 0 0" xyz="0 0 0"/>
      <geometry>
        <mesh filename="package://gripper_ocima/meshes/base_link.dae"/>
      </geometry>
      <material name="Orange">
        <!--<color rgba="1 0.49 0.31 1" />-->
      </material>
    </visual>
    <collision>
      <origin rpy="0 0 0" xyz="0 0 0"/>
      <geometry>
        <mesh filename="package://gripper_ocima/meshes/base_link.STL"/>
      </geometry>
    </collision>
  </link>
  <!-- END LINKS -->
  <!-- JOINTS -->
  <!-- joint 1 (A1) -->
  <joint name="right_joint_a1" type="revolute">
    <origin rpy="1.5708 0 0" xyz="0 0 0.47975"/>
    <parent link="right_base_link"/>
    <child link="right_link_1"/>
    <axis xyz="0 -1 0"/>
    <limit effort="0" lower="-3.22" upper="3.22" velocity="2.72271363311"/>
    <hardwareInterface>hardware_interface/PositionJointInterface</hardwareInterface>
  </joint>
  <!-- joint 2 (A2) -->
  <joint name="right_joint_a2" type="revolute">
    <origin rpy="-1.5708 0 0" xyz="0.35 0.33557 0.094"/>
    <parent link="right_link_1"/>
    <child link="right_link_2"/>
    <axis xyz="0 1 0"/>
    <limit effort="0" lower="-2.35" upper="0.61" velocity="2.72271363311"/>
    <hardwareInterface>hardware_interface/PositionJointInterface</hardwareInterface>
  </joint>
  <!-- joint 3 (A3) -->
  <joint name="right_joint_a3" type="revolute">
    <origin rpy="0 0 -0.011684" xyz="0.83287 -0.0097315 0"/>
    <parent link="right_link_2"/>
    <child link="right_link_3"/>
    <axis xyz="0 1 0"/>
    <limit effort="0" lower="-2.09" upper="2.75" velocity="2.72271363311"/>
    <hardwareInterface>hardware_interface/PositionJointInterface</hardwareInterface>
  </joint>
  <!-- joint 4 (A4) -->
  <joint name="right_joint_a4" type="revolute">
    <origin rpy="0 0 0" xyz="0.60824 0.089904 0.145"/>
    <parent link="right_link_3"/>
    <child link="right_link_4"/>
    <axis xyz="-1 0 0"/>
    <limit effort="0" lower="-6.1" upper="6.1" velocity="2.72271363311"/>
    <hardwareInterface>hardware_interface/PositionJointInterface</hardwareInterface>
  </joint>
  <!-- joint 5 (A5) -->
  <joint name="right_joint_a5" type="revolute">
    <origin rpy="0 -0.00079387 0.011684" xyz="0.41176 0 6.3846E-05"/>
    <parent link="right_link_4"/>
    <child link="right_link_5"/>
    <axis xyz="0.011683 0.99993 0"/>
    <limit effort="0" lower="-2.07" upper="2.07" velocity="5.75958653158"/>
    <hardwareInterface>hardware_interface/PositionJointInterface</hardwareInterface>
  </joint>
  <!-- joint 6 (A6) -->
  <joint name="right_joint_a6" type="revolute">
    <!--
      <origin xyz="0.12607 -3.6549E-05 -2.8142E-05" rpy="-0.67012 0.00079387 0"/>
			-->
    <origin rpy="0 0 0" xyz="0.12607 -3.6549E-05 -2.8142E-05"/>
    <parent link="right_link_5"/>
    <child link="right_link_6"/>
    <axis xyz="-1 0 0"/>
    <limit effort="0" lower="-6.1" upper="6.1" velocity="2.72271363311"/>
    <hardwareInterface>hardware_interface/PositionJointInterface</hardwareInterface>
  </joint>
  <!-- tool frame - fixed frame -->
  <joint name="right_joint_a6-tool0" type="fixed">
    <parent link="right_link_6"/>
    <child link="right_tool0"/>
    <origin rpy="0 1.57079632679 0" xyz="0.215 0 0"/>
    <hardwareInterface>hardware_interface/PositionJointInterface</hardwareInterface>
  </joint>
  <!-- gripper frame - fixed frame -->
  <joint name="right_tool0-gripper" type="fixed">
    <parent link="right_tool0"/>
    <child link="right_gripper"/>
    <origin rpy="-1.57079632679 0 1.57079632679" xyz="0.41 -0.33 -0.02"/>
  </joint>
  <!-- END JOINTS -->
  <!-- ROS base_link to KUKA $ROBROOT coordinate system transform  -->
  <joint name="right_grounding" type="fixed">
    <parent link="world"/>
    <child link="right_base_link"/>
    <origin rpy="0.0 0.0 0.0" xyz="0.0 0.0 0.0"/>
  </joint>
  <transmission name="tran1">
    <type>transmission_interface/SimpleTransmission</type>
    <joint name="right_joint_a1">
      <hardwareInterface>hardware_interface/PositionJointInterface</hardwareInterface>
    </joint>
    <actuator name="motor1">
      <hardwareInterface>hardware_interface/PositionJointInterface</hardwareInterface>
      <mechanicalReduction>1</mechanicalReduction>
    </actuator>
  </transmission>
  <transmission name="tran1">
    <type>transmission_interface/SimpleTransmission</type>
    <joint name="right_joint_a2">
      <hardwareInterface>hardware_interface/PositionJointInterface</hardwareInterface>
    </joint>
    <actuator name="motor1">
      <hardwareInterface>hardware_interface/PositionJointInterface</hardwareInterface>
      <mechanicalReduction>1</mechanicalReduction>
    </actuator>
  </transmission>
  <transmission name="tran1">
    <type>transmission_interface/SimpleTransmission</type>
    <joint name="right_joint_a3">
      <hardwareInterface>hardware_interface/PositionJointInterface</hardwareInterface>
    </joint>
    <actuator name="motor1">
      <hardwareInterface>hardware_interface/PositionJointInterface</hardwareInterface>
      <mechanicalReduction>1</mechanicalReduction>
    </actuator>
  </transmission>
  <transmission name="tran1">
    <type>transmission_interface/SimpleTransmission</type>
    <joint name="right_joint_a4">
      <hardwareInterface>hardware_interface/PositionJointInterface</hardwareInterface>
    </joint>
    <actuator name="motor1">
      <hardwareInterface>hardware_interface/PositionJointInterface</hardwareInterface>
      <mechanicalReduction>1</mechanicalReduction>
    </actuator>
  </transmission>
  <transmission name="tran1">
    <type>transmission_interface/SimpleTransmission</type>
    <joint name="right_joint_a5">
      <hardwareInterface>hardware_interface/PositionJointInterface</hardwareInterface>
    </joint>
    <actuator name="motor1">
      <hardwareInterface>hardware_interface/PositionJointInterface</hardwareInterface>
      <mechanicalReduction>1</mechanicalReduction>
    </actuator>
  </transmission>
  <transmission name="tran1">
    <type>transmission_interface/SimpleTransmission</type>
    <joint name="right_joint_a6">
      <hardwareInterface>hardware_interface/PositionJointInterface</hardwareInterface>
    </joint>
    <actuator name="motor1">
      <hardwareInterface>hardware_interface/PositionJointInterface</hardwareInterface>
      <mechanicalReduction>1</mechanicalReduction>
    </actuator>
  </transmission>
  <!-- ros_control plugin -->
  <gazebo>
    <plugin filename="libgazebo_ros_control.so" name="gazebo_ros_control">
      <robotNamespace>/kuka_kr60</robotNamespace>
    </plugin>
  </gazebo>
</robot>
